Workbook

Sheet PERSONAL
A6: REMUNERACIONES, HONORARIOS Y PAGOS ADICIONALES
A9: ITEM (Señalar nombre y cargo) | B9: INSTITUCIÓN O EMPRESA ASOCIADA | C9: HORAS QUE TRABAJARÁ AL MES PARA EL PROYECTO HH/MES | D9: MESES A CONTRATAR Nº | E9: HONORARIOS O REMUNERACIONES $ a pagar por MES | F9: TOTAL PROYECTO $
A12: DIRECTOR(A), DIRECTOR(A) ALTERNO(A), INVESTIGADORES(AS)
A13: Vicente Moreno | B13: Universidad Técnica Federico santa María | C13: 30 | D13: 3 | E13: 750080 | F13: =SUM(E13:E13)*D13 -> 2250240
A14: Yunis Vidal | B14: Universidad Técnica Federico santa María | C14: 30 | D14: 3 | E14: 750080 | F14: =SUM(E14:E14)*D14 -> 2250240
A15: Nicolas Rodriguez | B15: Universidad Técnica Federico santa María | C15: 30 | D15: 3 | E15: 750080 | F15: =SUM(E15:E15)*D15 -> 2250240
A16: Joaquin Ramirez | B16: Universidad Técnica Federico santa María | C16: 30 | D16: 3 | E16: 750080 | F16: =SUM(E16:E16)*D16 -> 2250240
F17: =SUM(E17:E17)*D17 -> 0
F18: =SUM(E18:E18)*D18 -> 0
F19: =SUM(E19:E19)*D19 -> 0
F20: =SUM(E20:E20)*D20 -> 0
F21: =SUM(E21:E21)*D21 -> 0
F22: =SUM(E22:E22)*D22 -> 0
F23: =SUM(E23:E23)*D23 -> 0
E24: 0 | F24: =SUM(E24:E24)*D24 -> 0
A25: SUBTOTAL | F25: =SUM(F13:F24) -> 9000960

Sheet EQUIPAMIENTO
A1: EQUIPOS | B1: EQUIPAMIENTO
A2: NOMBRE DEL EQUIPO Detalle los equipos individualmente | B2: INSTITUCIÓN O EMPRESA ASOCIADA | C2: DESCRIPCIÓN | D2: COSTO UNITARIO | F2: CANTIDAD UNIDADES O MESES | G2: TOTAL PROYECTO $
D3: ADQUISICIÓN EQUIPO $/UNIDAD | E3: USO UNIDADES EXISTENTES ($/MES)
A5: Amazon EC2 | B5: UTFSM | C5: Maquina virtuales de amazon para realizar los entrenamientos y calculos del software. | D5: 0 | E5: 171764 | F5: 19 | G5: =(D5+E5)*F5 -> 3263516
A6: Computadores para el proyecto | B6: UTFSM | C6: 6 Notebooks Lenovo Thinkpad T480 14 Pulg i5-7300U 8gb 256gb SSD Reacondicionado Grado A | D6: 400000 | E6: 0 | F6: 4 | G6: =(D6+E6)*F6 -> 1600000
A7: Mouse Razer DeathAdder | B7: UTFSM | C7: 4 mouse para equipos | D7: 39900 | E7: 0 | F7: 4 | G7: =(D7+E7)*F7 -> 159600
A8: Silla de oficina Gamer Profesional Ulrik Negra | B8: UTFSM | C8: 4 sillas para equipo | D8: 259990 | F8: 4 | G8: =(D8+E8)*F8 -> 1039960
A9: Memoria RAM | B9: UTFSM | C9: 32 GB de memoria RAM | D9: 600000 | E9: 0 | F9: 1 | G9: =(D9+E9)*F9 -> 600000
D10: 0 | E10: 0 | F10: 0 | G10: =(D10+E10)*F10 -> 0
D11: 0 | E11: 0 | F11: 0 | G11: =(D11+E11)*F11 -> 0
D12: 0 | E12: 0 | F12: 0 | G12: =(D12+E12)*F12 -> 0
D13: 0 | E13: 0 | F13: 0 | G13: =(D13+E13)*F13 -> 0
D14: 0 | E14: 0 | F14: 0 | G14: =(D14+E14)*F14 -> 0
D15: 0 | E15: 0 | F15: 0 | G15: =(D15+E15)*F15 -> 0
D16: 0 | E16: 0 | F16: 0 | G16: =(D16+E16)*F16 -> 0
D17: 0 | E17: 0 | F17: 0 | G17: =(D17+E17)*F17 -> 0
D18: 0 | E18: 0 | F18: 0 | G18: =(D18+E18)*F18 -> 0
D19: 0 | E19: 0 | F19: 0 | G19: =(D19+E19)*F19 -> 0
D20: 0 | E20: 0 | F20: 0 | G20: =(D20+E20)*F20 -> 0
D21: 0 | E21: 0 | F21: 0 | G21: =(D21+E21)*F21 -> 0
... D24: 0 | E24: 0 | F24: 0 | G24: =(D24+E24)*F24 -> 0
A25: SUBTOTAL | G25: =SUM(G5:G24) -> 6663076

Sheet INFRAESTRUCTURA Y MOBILIARIO
A1: INFRAESTRUCTURA | B1: INFRAESTRUCTURA Y MOBILIARIO
A2: NOMBRE DE LA INFRAESTRUCTURA | B2: INSTITUCIÓN O EMPRESA ASOCIADA | C2: DESCRIPCIÓN | D2: COSTO UNITARIO | F2: CANTIDAD UNIDADES O MESES | G2: TOTAL PROYECTO $
D3: CASO ADQUISICIONES O HABILITACIÓN (M$/UNIDAD) | E3: USO UNIDADES EXISTENTES ($/MES)
A5: Piso de Trabajo y reuniones | B5: Universidad de Santiago | C5: Lugar de trabajo para investigadores y de reuniones para equipo completo. | D5: 0 | E5: 10000 | F5: 24 | G5: =(D5+E5)*F5 -> 240000
A6: Laboratorio de Computación | B6: Universidad de Santiago | C6: Laboratorio con computadores para la parte informática del proyecto | D6: 0 | E6: 5000 | F6: 19 | G6: =(D6+E6)*F6 -> 95000
D7: 0 | E7: 0 | F7: 0 | G7: =(D7+E7)*F7 -> 0
D8: 0 | E8: 0 | F8: 0 | G8: =(D8+E8)*F8 -> 0
D9: 0 | E9: 0 | F9: 0 | G9: =(D9+E9)*F9 -> 0
D10: 0 | E10: 0 | F10: 0 | G10: =(D10+E10)*F10 -> 0
D11: 0 | E11: 0 | F11: 0 | G11: =(D11+E11)*F11 -> 0
D12: 0 | E12: 0 | F12: 0 | G12: =(D12+E12)*F12 -> 0
A13: SUBTOTAL | G13: =SUM(G5:G12) -> 335000

Sheet GASTOS OPERACION
A5: MATERIAL FUNGIBLE
A6: DESCRIPCIÓN | B6: INSTITUCIÓN O EMPRESA ASOCIADA | C6: COSTO UNITARIO $/UNIDAD | D6: CANTIDAD | E6: TOTAL PROYECTO $
A9: Hojas, luz y agua | B9: UFTSM | C9: 5000 | D9: 400 | E9: =C9*D9 -> 2000000
A10: Materiales de Escritorio | B10: UFTSM | C10: 10000 | D10: 400 | E10: =C10*D10 -> 4000000
A11: Comida | B11: UFTSM | C11: 6000 | D11: 120 | E11: =C11*D11 -> 720000
C12: 0 | D12: 0 | E12: =C12*D12 -> 0
C13: 0 | D13: 0 | E13: =C13*D13 -> 0
C14: 0 | D14: 0 | E14: =C14*D14 -> 0
C15: 0 | D15: 0 | E15: =C15*D15 -> 0
C16: 0 | D16: 0 | E16: =C16*D16 -> 0
C17: 0 | D17: 0 | E17: =C17*D17 -> 0
C18: 0 | D18: 0 | E18: =C18*D18 -> 0
A19: SUBTOTAL | E19: =SUM(E9:E18) -> 6720000
A22: SOFTWARE
A23: DESCRIPCIÓN Los softwares de uso general no son financiados por ANID | B23: INSTITUCIÓN O EMPRESA ASOCIADA | C23: COSTO UNITARIO $/UNIDAD | D23: CANTIDAD | E23: TOTAL PROYECTO $
A26: Python | B26: UTFSM | C26: 5000 | D26: 5 | E26: =C26*D26 -> 25000
C27: 0 | D27: 0 | E27: =C27*D27 -> 0
C28: 0 | D28: 0 | E28: =C28*D28 -> 0
C29: 0 | D29: 0 | E29: =C29*D29 -> 0
A30: SUBTOTAL | E30: =SUM(E26:E29) -> 25000
G60: TOTAL $
G63: =SUM(F63:F63) -> 0
G64: =SUM(F64:F64) -> 0
G65: =SUM(F65:F65) -> 0
G66: =SUM(F66:F66) -> 0
G67: =SUM(F67:F67) -> 0
G68: =SUM(F68:F68) -> 0
G69: =SUM(F69:F69) -> 0
G70: =SUM(F70:F70) -> 0
G71: =SUM(F71:F71) -> 0
G72: =SUM(G63:G71) -> 0
G73: =IF(G72=#REF!,"Monto Total Validado","Error. Existe Diferencia entre Total y Total Proyecto") -> #REF!

Sheet RESUMEN GASTOS OPERACION
A1: RESUMEN GASTOS DE OPERACIÓN
A4: DESCRIPCIÓN | B4: TOTAL $
A7: MATERIAL FUNGIBLE | B7: ='GASTOS OPERACION'!E19 -> 6720000
A8: SOFTWARE | B8: ='GASTOS OPERACION'!E30 -> 25000
A9: SUBCONTRATOS | B9: 0
A10: PASAJES | B10: 0
A11: VIATICOS | B11: 0
A12: PROPIEDAD INTELECTUAL | B12: 0
A13: SEMINARIOS, PUBLICACIONES Y DIFUSION | B13: 0
A14: CAPACITACION | B14: 0
A15: OTROS GASTOS DE OPERACIÓN | B15: 0
A16: SUBTOTAL | B16: =SUM(B7:B15) -> 6745000

Sheet TOTAL
A3: COSTO TOTAL DEL PROYECTO
A4: ITEM | B4: COSTO TOTAL $
A7: GASTOS EN PERSONAL | B7: =PERSONAL!F25 -> 9000960
A8: EQUIPAMIENTO | B8: =EQUIPAMIENTO!G25 -> 6663076
A9: INFRAESTRUCTURA Y MOBILILARIO | B9: ='INFRAESTRUCTURA Y MOBILIARIO'!G13 -> 335000
A10: GASTOS DE OPERACIÓN | B10: ='RESUMEN GASTOS OPERACION'!B16 -> 6745000
A11: TOTAL | B11: =SUM(B7:B10) -> 22744036

Sheet REITEMIZACIONES FONDEF
A1: HISTORIAL REITEMIZACIONES: En esta hoja deben quedar reflejadas todas la reitemizaciones realizadas por el proyecto al presupuesto del subsidio ANID con su respectiva justificación. El proyecto debe programar estás reitemizaciones con una periodicidad de seis meses.
A3: MODIFICACIÓN PRESUPUESTARIA 1
A4: FECHA
A5: INSTITUCIÓN FINANCIADORA | B5: ANID
A6: INSTITUCIÓN EJECUTORA
A8: ITEM | B8: PRESUPUESTO ACTUAL | C8: PRESUPUESTO MODIFICADO | D8: JUSTIFICACIÓN DE LA REITEMIZACIÓN
A9: GASTOS EN PERSONAL | B9: 0 | C9: 0
A10: EQUIPOS | B10: 0 | C10: 0
A11: INFRAESTRUCTURA | B11: 0 | C11: 0
A12: GASTOS DE OPERACIÓN | B12: 0 | C12: 0
A13: GASTOS DE ADM. SUPERIOR | B13: 0 | C13: 0
A14: TOTALES | B14: =SUM(B9:B13) -> 0 | C14: =SUM(C9:C13) -> 0 | D14: =IF(B14=C14,"PRESUPUESTO VALIDADO","CORREGIR DIFERENCIA") -> PRESUPUESTO VALIDADO
A16: MODIFICACIÓN PRESUPUESTARIA 2
A17: FECHA
A18: INSTITUCIÓN FINANCIADORA | B18: ANID
A19: INSTITUCIÓN EJECUTORA
A21: ITEM | B21: PRESUPUESTO ACTUAL | C21: PRESUPUESTO MODIFICADO | D21: JUSTIFICACIÓN DE LA REITEMIZACIÓN
A22: GASTOS EN PERSONAL | B22: 0 | C22: 0
A23: EQUIPOS | B23: 0 | C23: 0
A24: INFRAESTRUCTURA | B24: 0 | C24: 0
A25: GASTOS DE OPERACIÓN | B25: 0 | C25: 0
A26: GASTOS DE ADM. SUPERIOR | B26: 0 | C26: 0
A27: TOTALES | B27: =SUM(B22:B26) -> 0 | C27: =SUM(C22:C26) -> 0 | D27: =IF(B27=C27,"PRESUPUESTO VALIDADO","CORREGIR DIFERENCIA") -> PRESUPUESTO VALIDADO
A29: MODIFICACIÓN PRESUPUESTARIA 3
A30: FECHA
A31: INSTITUCIÓN FINANCIADORA | B31: ANID
A32: INSTITUCIÓN EJECUTORA
A34: ITEM | B34: PRESUPUESTO ACTUAL | C34: PRESUPUESTO MODIFICADO | D34: JUSTIFICACIÓN DE LA REITEMIZACIÓN
A35: GASTOS EN PERSONAL | B35: 0 | C35: 0
A36: EQUIPOS | B36: 0 | C36: 0
A37: INFRAESTRUCTURA | B37: 0 | C37: 0
A38: GASTOS DE OPERACIÓN | B38: 0 | C38: 0
A39: GASTOS DE ADM. SUPERIOR | B39: 0 | C39: 0
A40: TOTALES | B40: =SUM(B35:B39) -> 0 | C40: =SUM(C35:C39) -> 0 | D40: =IF(B40=C40,"PRESUPUESTO VALIDADO","CORREGIR DIFERENCIA") -> PRESUPUESTO VALIDADO
A42: MODIFICACIÓN PRESUPUESTARIA 4
A43: FECHA
A44: INSTITUCIÓN FINANCIADORA | B44: ANID
A45: INSTITUCIÓN EJECUTORA
A47: ITEM | B47: PRESUPUESTO ACTUAL | C47: PRESUPUETO MODIFICADO | D47: JUSTIFICACIÓN DE LA REITEMIZACIÓN
A48: GASTOS EN PERSONAL | B48: 0 | C48: 0
...

Sheet REITEMIZACIONES OTROS PPTOS
A1: HISTORIAL REITEMIZACIONES: En esta hoja deben quedar reflejadas todas la reitemizaciones realizadas por el proyecto al presupuesto de la Entidad(es) Beneficiaria(s) y Entidad(es) Asociada(s) con su respectiva justificación. El proyecto debe programar estas reitemizaciones con una periodicidad de seis meses.
A3: MODIFICACIÓN PRESUPUESTARIA 1
A4: FECHA
A5: INSTITUCIÓN FINANCIADORA
A6: INSTITUCIÓN EJECUTORA
A8: ITEM | B8: PRESUPUESTO ACTUAL | C8: PRESUPUESTO MODIFICADO | D8: JUSTIFICACIÓN DE LA REITEMIZACIÓN
A9: GASTOS EN PERSONAL | B9: 0 | C9: 0
A10: EQUIPOS | B10: 0 | C10: 0
A11: INFRAESTRUCTURA | B11: 0 | C11: 0
A12: GASTOS DE OPERACIÓN | B12: 0 | C12: 0
A13: GASTOS DE ADM. SUPERIOR | B13: 0 | C13: 0
A14: TOTALES | B14: =SUM(B9:B13) -> 0 | C14: =SUM(C9:C13) -> 0 | D14: =IF(B14=C14,"PRESUPUESTO VALIDADO","CORREGIR DIFERENCIA") -> PRESUPUESTO VALIDADO
A16: MODIFICACIÓN PRESUPUESTARIA 2
A17: FECHA
A18: INSTITUCIÓN FINANCIADORA
A19: INSTITUCIÓN EJECUTORA
A21: ITEM | B21: PRESUPUESTO ACTUAL | C21: PRESUPUESTO MODIFICADO | D21: JUSTIFICACIÓN DE LA REITEMIZACIÓN
A22: GASTOS EN PERSONAL | B22: 0 | C22: 0
A23: EQUIPOS | B23: 0 | C23: 0
A24: INFRAESTRUCTURA | B24: 0 | C24: 0
A25: GASTOS DE OPERACIÓN | B25: 0 | C25: 0
A26: GASTOS DE ADM. SUPERIOR | B26: 0 | C26: 0
A27: TOTALES | B27: =SUM(B22:B26) -> 0 | C27: =SUM(C22:C26) -> 0 | D27: =IF(B27=C27,"PRESUPUESTO VALIDADO","CORREGIR DIFERENCIA") -> PRESUPUESTO VALIDADO
A29: MODIFICACIÓN PRESUPUESTARIA 3
A30: FECHA
A31: INSTITUCIÓN FINANCIADORA
A32: INSTITUCIÓN EJECUTORA
A34: ITEM | B34: PRESUPUESTO ACTUAL | C34: PRESUPUESTO MODIFICADO | D34: JUSTIFICACIÓN DE LA REITEMIZACIÓN
A35: GASTOS EN PERSONAL | B35: 0 | C35: 0
A36: EQUIPOS | B36: 0 | C36: 0
A37: INFRAESTRUCTURA | B37: 0 | C37: 0
A38: GASTOS DE OPERACIÓN | B38: 0 | C38: 0
A39: GASTOS DE ADM. SUPERIOR | B39: 0 | C39: 0
A40: TOTALES | B40: =SUM(B35:B39) -> 0 | C40: =SUM(C35:C39) -> 0 | D40: =IF(B40=C40,"PRESUPUESTO VALIDADO","CORREGIR DIFERENCIA") -> PRESUPUESTO VALIDADO
A42: MODIFICACIÓN PRESUPUESTARIA 4
A43: FECHA
A44: INSTITUCIÓN FINANCIADORA
A45: INSTITUCIÓN EJECUTORA
A47: ITEM | B47: PRESUPUESTO ACTUAL | C47: PRESUPUETO MODIFICADO | D47: JUSTIFICACIÓN DE LA REITEMIZACIÓN
A48: GASTOS EN PERSONAL | B48: 0 | C48: 0
...
